Loading python/3.11.6--gcc--8.5.0
  Loading requirement: bzip2/1.0.8-gp5wcz5 libmd/1.0.4-wja3f5q
    libbsd/0.11.7-cgxjopl expat/2.5.0-bptl3xw ncurses/6.4-asx3jea
    readline/8.2-nyw6mp6 gdbm/1.23-fs6otck libiconv/1.17-d7yvx2s
    xz/5.4.1-hubmwr5 zlib-ng/2.1.4-6htiapk libxml2/2.10.3-5eeeokp
    pigz/2.7-bopr5vp zstd/1.5.5-gawytfl tar/1.34-amqus5s gettext/0.22.3-2g7elif
    libffi/3.4.4-6r7brdq libxcrypt/4.4.35-ss2rzin sqlite/3.43.2
    util-linux-uuid/2.38.1-jkdi7kv
Running on  nodes
---------------------------------------------
SLURM job ID:        13458739
SLURM job node list: lrdn2630
DATE:                Wed Mar  5 11:26:42 CET 2025
---------------------------------------------
Traceback (most recent call last):
  File "/leonardo/home/userexternal/scanduss/transformers/src/transformers/utils/hub.py", line 403, in cached_file
    resolved_file = hf_hub_download(
                    ^^^^^^^^^^^^^^^^
  File "/leonardo/home/userexternal/scanduss/.venv/lib/python3.11/site-packages/huggingface_hub/utils/_validators.py", line 106, in _inner_fn
    validate_repo_id(arg_value)
  File "/leonardo/home/userexternal/scanduss/.venv/lib/python3.11/site-packages/huggingface_hub/utils/_validators.py", line 154, in validate_repo_id
    raise HFValidationError(
huggingface_hub.errors.HFValidationError: Repo id must be in the form 'repo_name' or 'namespace/repo_name': '../../../../../../../../../leonardo_scratch/fast/IscrC_IRA-LLMs/hardskewed_@/step_9000'. Use `repo_type` argument if needed.

The above exception was the direct cause of the following exception:

Traceback (most recent call last):
  File "/leonardo/home/userexternal/scanduss/transformers/src/transformers/models/stldec/validate_h_9k.py", line 37, in <module>
    model = AutoModelForCausalLM.from_pretrained(model_path, config = config).to(device)  # Sposta il modello sulla device
            ^^^^^^^^^^^^^^^^^^^^^^^^^^^^^^^^^^^^^^^^^^^^^^^^^^^^^^^^^^^^^^^^^
  File "/leonardo/home/userexternal/scanduss/transformers/src/transformers/models/auto/auto_factory.py", line 564, in from_pretrained
    return model_class.from_pretrained(
           ^^^^^^^^^^^^^^^^^^^^^^^^^^^^
  File "/leonardo/home/userexternal/scanduss/transformers/src/transformers/modeling_utils.py", line 3825, in from_pretrained
    resolved_archive_file = cached_file(pretrained_model_name_or_path, filename, **cached_file_kwargs)
                            ^^^^^^^^^^^^^^^^^^^^^^^^^^^^^^^^^^^^^^^^^^^^^^^^^^^^^^^^^^^^^^^^^^^^^^^^^^
  File "/leonardo/home/userexternal/scanduss/transformers/src/transformers/utils/hub.py", line 469, in cached_file
    raise EnvironmentError(
OSError: Incorrect path_or_model_id: '../../../../../../../../../leonardo_scratch/fast/IscrC_IRA-LLMs/hardskewed_@/step_9000'. Please provide either the path to a local folder or the repo_id of a model on the Hub.
srun: error: lrdn2630: task 0: Exited with exit code 1
DONE!
